INFO:root:Anonymized telemetry enabled. See https://docs.browser-use.com/development/telemetry for more information.
2025-04-21 17:45:29.786 | INFO     | app.mcp.server:register_tool:76 - Registered tool: bash
2025-04-21 17:45:29.788 | INFO     | app.mcp.server:register_tool:76 - Registered tool: browser_use
2025-04-21 17:45:29.789 | INFO     | app.mcp.server:register_tool:76 - Registered tool: str_replace_editor
2025-04-21 17:45:29.789 | INFO     | app.mcp.server:register_tool:76 - Registered tool: terminate
2025-04-21 17:45:29.789 | INFO     | app.mcp.server:run:159 - Starting OpenManus server (stdio mode)
  + Exception Group Traceback (most recent call last):
  |   File "/Users/lizhong01/Documents/OpenManus/run_mcp_server.py", line 11, in <module>
  |     server.run(transport=args.transport)
  |   File "/Users/lizhong01/Documents/OpenManus/app/mcp/server.py", line 160, in run
  |     self.server.run(transport=transport)
  |   File "/Users/lizhong01/Documents/OpenManus/manus/lib/python3.12/site-packages/mcp/server/fastmcp/server.py", line 159, in run
  |     anyio.run(self.run_stdio_async)
  |   File "/Users/lizhong01/Documents/OpenManus/manus/lib/python3.12/site-packages/anyio/_core/_eventloop.py", line 74, in run
  |     return async_backend.run(func, args, {}, backend_options)
  |            ^^^^^^^^^^^^^^^^^^^^^^^^^^^^^^^^^^^^^^^^^^^^^^^^^^
  |   File "/Users/lizhong01/Documents/OpenManus/manus/lib/python3.12/site-packages/anyio/_backends/_asyncio.py", line 2310, in run
  |     return runner.run(wrapper())
  |            ^^^^^^^^^^^^^^^^^^^^^
  |   File "/opt/anaconda3/lib/python3.12/asyncio/runners.py", line 118, in run
  |     return self._loop.run_until_complete(task)
  |            ^^^^^^^^^^^^^^^^^^^^^^^^^^^^^^^^^^^
  |   File "/opt/anaconda3/lib/python3.12/asyncio/base_events.py", line 687, in run_until_complete
  |     return future.result()
  |            ^^^^^^^^^^^^^^^
  |   File "/Users/lizhong01/Documents/OpenManus/manus/lib/python3.12/site-packages/anyio/_backends/_asyncio.py", line 2298, in wrapper
  |     return await func(*args)
  |            ^^^^^^^^^^^^^^^^^
  |   File "/Users/lizhong01/Documents/OpenManus/manus/lib/python3.12/site-packages/mcp/server/fastmcp/server.py", line 460, in run_stdio_async
  |     async with stdio_server() as (read_stream, write_stream):
  |                ^^^^^^^^^^^^^^
  |   File "/opt/anaconda3/lib/python3.12/contextlib.py", line 217, in __aexit__
  |     await anext(self.gen)
  |   File "/Users/lizhong01/Documents/OpenManus/manus/lib/python3.12/site-packages/mcp/server/stdio.py", line 83, in stdio_server
  |     async with anyio.create_task_group() as tg:
  |                ^^^^^^^^^^^^^^^^^^^^^^^^^
  |   File "/Users/lizhong01/Documents/OpenManus/manus/lib/python3.12/site-packages/anyio/_backends/_asyncio.py", line 772, in __aexit__
  |     raise BaseExceptionGroup(
  | ExceptionGroup: unhandled errors in a TaskGroup (1 sub-exception)
  +-+---------------- 1 ----------------
    | Traceback (most recent call last):
    |   File "/Users/lizhong01/Documents/OpenManus/manus/lib/python3.12/site-packages/mcp/server/stdio.py", line 62, in stdin_reader
    |     async for line in stdin:
    |   File "/Users/lizhong01/Documents/OpenManus/manus/lib/python3.12/site-packages/anyio/_core/_fileio.py", line 83, in __aiter__
    |     line = await self.readline()
    |            ^^^^^^^^^^^^^^^^^^^^^
    |   File "/Users/lizhong01/Documents/OpenManus/manus/lib/python3.12/site-packages/anyio/_core/_fileio.py", line 99, in readline
    |     return await to_thread.run_sync(self._fp.readline)
    |            ^^^^^^^^^^^^^^^^^^^^^^^^^^^^^^^^^^^^^^^^^^^
    |   File "/Users/lizhong01/Documents/OpenManus/manus/lib/python3.12/site-packages/anyio/to_thread.py", line 56, in run_sync
    |     return await get_async_backend().run_sync_in_worker_thread(
    |            ^^^^^^^^^^^^^^^^^^^^^^^^^^^^^^^^^^^^^^^^^^^^^^^^^^^^
    |   File "/Users/lizhong01/Documents/OpenManus/manus/lib/python3.12/site-packages/anyio/_backends/_asyncio.py", line 2470, in run_sync_in_worker_thread
    |     return await future
    |            ^^^^^^^^^^^^
    |   File "/Users/lizhong01/Documents/OpenManus/manus/lib/python3.12/site-packages/anyio/_backends/_asyncio.py", line 967, in run
    |     result = context.run(func, *args)
    |              ^^^^^^^^^^^^^^^^^^^^^^^^
    | OSError: [Errno 5] Input/output error
    +------------------------------------
2025-04-21 18:51:33.650 | INFO     | app.mcp.server:cleanup:140 - Cleaning up resources
INFO:root:Anonymized telemetry enabled. See https://docs.browser-use.com/development/telemetry for more information.
2025-04-22 17:28:14.334 | INFO     | app.mcp.server:register_tool:76 - Registered tool: bash
2025-04-22 17:28:14.336 | INFO     | app.mcp.server:register_tool:76 - Registered tool: browser_use
2025-04-22 17:28:14.337 | INFO     | app.mcp.server:register_tool:76 - Registered tool: str_replace_editor
2025-04-22 17:28:14.337 | INFO     | app.mcp.server:register_tool:76 - Registered tool: terminate
2025-04-22 17:28:14.337 | INFO     | app.mcp.server:run:159 - Starting OpenManus server (stdio mode)
  + Exception Group Traceback (most recent call last):
  |   File "/Users/lizhong01/Documents/OpenManus/run_mcp_server.py", line 11, in <module>
  |     server.run(transport=args.transport)
  |   File "/Users/lizhong01/Documents/OpenManus/app/mcp/server.py", line 160, in run
  |     self.server.run(transport=transport)
  |   File "/Users/lizhong01/Documents/OpenManus/manus/lib/python3.12/site-packages/mcp/server/fastmcp/server.py", line 159, in run
  |     anyio.run(self.run_stdio_async)
  |   File "/Users/lizhong01/Documents/OpenManus/manus/lib/python3.12/site-packages/anyio/_core/_eventloop.py", line 74, in run
  |     return async_backend.run(func, args, {}, backend_options)
  |            ^^^^^^^^^^^^^^^^^^^^^^^^^^^^^^^^^^^^^^^^^^^^^^^^^^
  |   File "/Users/lizhong01/Documents/OpenManus/manus/lib/python3.12/site-packages/anyio/_backends/_asyncio.py", line 2310, in run
  |     return runner.run(wrapper())
  |            ^^^^^^^^^^^^^^^^^^^^^
  |   File "/opt/anaconda3/lib/python3.12/asyncio/runners.py", line 118, in run
  |     return self._loop.run_until_complete(task)
  |            ^^^^^^^^^^^^^^^^^^^^^^^^^^^^^^^^^^^
  |   File "/opt/anaconda3/lib/python3.12/asyncio/base_events.py", line 687, in run_until_complete
  |     return future.result()
  |            ^^^^^^^^^^^^^^^
  |   File "/Users/lizhong01/Documents/OpenManus/manus/lib/python3.12/site-packages/anyio/_backends/_asyncio.py", line 2298, in wrapper
  |     return await func(*args)
  |            ^^^^^^^^^^^^^^^^^
  |   File "/Users/lizhong01/Documents/OpenManus/manus/lib/python3.12/site-packages/mcp/server/fastmcp/server.py", line 460, in run_stdio_async
  |     async with stdio_server() as (read_stream, write_stream):
  |                ^^^^^^^^^^^^^^
  |   File "/opt/anaconda3/lib/python3.12/contextlib.py", line 217, in __aexit__
  |     await anext(self.gen)
  |   File "/Users/lizhong01/Documents/OpenManus/manus/lib/python3.12/site-packages/mcp/server/stdio.py", line 83, in stdio_server
  |     async with anyio.create_task_group() as tg:
  |                ^^^^^^^^^^^^^^^^^^^^^^^^^
  |   File "/Users/lizhong01/Documents/OpenManus/manus/lib/python3.12/site-packages/anyio/_backends/_asyncio.py", line 772, in __aexit__
  |     raise BaseExceptionGroup(
  | ExceptionGroup: unhandled errors in a TaskGroup (1 sub-exception)
  +-+---------------- 1 ----------------
    | Traceback (most recent call last):
    |   File "/Users/lizhong01/Documents/OpenManus/manus/lib/python3.12/site-packages/mcp/server/stdio.py", line 62, in stdin_reader
    |     async for line in stdin:
    |   File "/Users/lizhong01/Documents/OpenManus/manus/lib/python3.12/site-packages/anyio/_core/_fileio.py", line 83, in __aiter__
    |     line = await self.readline()
    |            ^^^^^^^^^^^^^^^^^^^^^
    |   File "/Users/lizhong01/Documents/OpenManus/manus/lib/python3.12/site-packages/anyio/_core/_fileio.py", line 99, in readline
    |     return await to_thread.run_sync(self._fp.readline)
    |            ^^^^^^^^^^^^^^^^^^^^^^^^^^^^^^^^^^^^^^^^^^^
    |   File "/Users/lizhong01/Documents/OpenManus/manus/lib/python3.12/site-packages/anyio/to_thread.py", line 56, in run_sync
    |     return await get_async_backend().run_sync_in_worker_thread(
    |            ^^^^^^^^^^^^^^^^^^^^^^^^^^^^^^^^^^^^^^^^^^^^^^^^^^^^
    |   File "/Users/lizhong01/Documents/OpenManus/manus/lib/python3.12/site-packages/anyio/_backends/_asyncio.py", line 2470, in run_sync_in_worker_thread
    |     return await future
    |            ^^^^^^^^^^^^
    |   File "/Users/lizhong01/Documents/OpenManus/manus/lib/python3.12/site-packages/anyio/_backends/_asyncio.py", line 967, in run
    |     result = context.run(func, *args)
    |              ^^^^^^^^^^^^^^^^^^^^^^^^
    | OSError: [Errno 5] Input/output error
    +------------------------------------
2025-04-23 16:25:02.684 | INFO     | app.mcp.server:cleanup:140 - Cleaning up resources
